Workbook

Sheet Summary
A1: Tỷ lệ BD Grade B- — T8 / T9 / T10 MTD (15/10/2026) — toàn bộ BD có grade
A2: %B- = #B- ÷ #BD có grade hợp lệ (A+/A/B+/B/B-/C) trong tháng. Loại grade "-" (MOB0) và ô trống (chưa vào / đã nghỉ). Công thức COUNTIFS trỏ về sheet Data.
A4: Total
A5: Total | B5: T8 | E5: T9 | H5: T10 MTD | K5: Δ %B- T10 vs T8
B6: #B- | C6: #Graded | D6: %B- | E6: #B- | F6: #Graded | G6: %B- | H6: #B- | I6: #Graded | J6: %B- | K6: (điểm %)
A7: Total | B7: =COUNTIFS(Data!$J$2:$J$334,"B-") -> 22 | C7: =SUMPRODUCT(COUNTIFS(Data!$J$2:$J$334,{"A+","A","B+","B","B-","C"})) -> 231 | D7: =IF(C7=0,"",B7/C7) -> 0.095238095 | E7: =COUNTIFS(Data!$K$2:$K$334,"B-") -> 23 | F7: =SUMPRODUCT(COUNTIFS(Data!$K$2:$K$334,{"A+","A","B+","B","B-","C"})) -> 249 | G7: =IF(F7=0,"",E7/F7) -> 0.092369478 | H7: =COUNTIFS(Data!$L$2:$L$334,"B-") -> 25 | I7: =SUMPRODUCT(COUNTIFS(Data!$L$2:$L$334,{"A+","A","B+","B","B-","C"})) -> 243 | J7: =IF(I7=0,"",H7/I7) -> 0.10288066 | K7: =IF(OR(D7="",J7=""),"",(J7-D7)*100) -> 0.76425632
A9: Region
A10: Region | B10: T8 | E10: T9 | H10: T10 MTD | K10: Δ %B- T10 vs T8
B11: #B- | C11: #Graded | D11: %B- | E11: #B- | F11: #Graded | G11: %B- | H11: #B- | I11: #Graded | J11: %B- | K11: (điểm %)
A12: North | B12: =COUNTIFS(Data!$J$2:$J$334,"B-",Data!$C$2:$C$334,"North") -> 17 | C12: =SUMPRODUCT(COUNTIFS(Data!$J$2:$J$334,{"A+","A","B+","B","B-","C"},Data!$C$2:$C$334,"North")) -> 143 | D12: =IF(C12=0,"",B12/C12) -> 0.11888112 | E12: =COUNTIFS(Data!$K$2:$K$334,"B-",Data!$C$2:$C$334,"North") -> 13 | F12: =SUMPRODUCT(COUNTIFS(Data!$K$2:$K$334,{"A+","A","B+","B","B-","C"},Data!$C$2:$C$334,"North")) -> 150 | G12: =IF(F12=0,"",E12/F12) -> 0.086666667 | H12: =COUNTIFS(Data!$L$2:$L$334,"B-",Data!$C$2:$C$334,"North") -> 11 | I12: =SUMPRODUCT(COUNTIFS(Data!$L$2:$L$334,{"A+","A","B+","B","B-","C"},Data!$C$2:$C$334,"North")) -> 146 | J12: =IF(I12=0,"",H12/I12) -> 0.075342466 | K12: =IF(OR(D12="",J12=""),"",(J12-D12)*100) -> -4.3538653
A13: South | B13: =COUNTIFS(Data!$J$2:$J$334,"B-",Data!$C$2:$C$334,"South") -> 5 | C13: =SUMPRODUCT(COUNTIFS(Data!$J$2:$J$334,{"A+","A","B+","B","B-","C"},Data!$C$2:$C$334,"South")) -> 88 | D13: =IF(C13=0,"",B13/C13) -> 0.056818182 | E13: =COUNTIFS(Data!$K$2:$K$334,"B-",Data!$C$2:$C$334,"South") -> 10 | F13: =SUMPRODUCT(COUNTIFS(Data!$K$2:$K$334,{"A+","A","B+","B","B-","C"},Data!$C$2:$C$334,"South")) -> 99 | G13: =IF(F13=0,"",E13/F13) -> 0.1010101 | H13: =COUNTIFS(Data!$L$2:$L$334,"B-",Data!$C$2:$C$334,"South") -> 14 | I13: =SUMPRODUCT(COUNTIFS(Data!$L$2:$L$334,{"A+","A","B+","B","B-","C"},Data!$C$2:$C$334,"South")) -> 97 | J13: =IF(I13=0,"",H13/I13) -> 0.1443299 | K13: =IF(OR(D13="",J13=""),"",(J13-D13)*100) -> 8.7511715
A15: Segment
A16: Segment | B16: T8 | E16: T9 | H16: T10 MTD | K16: Δ %B- T10 vs T8
B17: #B- | C17: #Graded | D17: %B- | E17: #B- | F17: #Graded | G17: %B- | H17: #B- | I17: #Graded | J17: %B- | K17: (điểm %)
A18: FS | B18: =COUNTIFS(Data!$J$2:$J$334,"B-",Data!$D$2:$D$334,"FS") -> 10 | C18: =SUMPRODUCT(COUNTIFS(Data!$J$2:$J$334,{"A+","A","B+","B","B-","C"},Data!$D$2:$D$334,"FS")) -> 96 | D18: =IF(C18=0,"",B18/C18) -> 0.10416667 | E18: =COUNTIFS(Data!$K$2:$K$334,"B-",Data!$D$2:$D$334,"FS") -> 7 | F18: =SUMPRODUCT(COUNTIFS(Data!$K$2:$K$334,{"A+","A","B+","B","B-","C"},Data!$D$2:$D$334,"FS")) -> 109 | G18: =IF(F18=0,"",E18/F18) -> 0.064220183 | H18: =COUNTIFS(Data!$L$2:$L$334,"B-",Data!$D$2:$D$334,"FS") -> 3 | I18: =SUMPRODUCT(COUNTIFS(Data!$L$2:$L$334,{"A+","A","B+","B","B-","C"},Data!$D$2:$D$334,"FS")) -> 99 | J18: =IF(I18=0,"",H18/I18) -> 0.03030303 | K18: =IF(OR(D18="",J18=""),"",(J18-D18)*100) -> -7.3863636
A19: SME | B19: =COUNTIFS(Data!$J$2:$J$334,"B-",Data!$D$2:$D$334,"SME") -> 12 | C19: =SUMPRODUCT(COUNTIFS(Data!$J$2:$J$334,{"A+","A","B+","B","B-","C"},Data!$D$2:$D$334,"SME")) -> 131 | D19: =IF(C19=0,"",B19/C19) -> 0.091603053 | E19: =COUNTIFS(Data!$K$2:$K$334,"B-",Data!$D$2:$D$334,"SME") -> 16 | F19: =SUMPRODUCT(COUNTIFS(Data!$K$2:$K$334,{"A+","A","B+","B","B-","C"},Data!$D$2:$D$334,"SME")) -> 137 | G19: =IF(F19=0,"",E19/F19) -> 0.11678832 | H19: =COUNTIFS(Data!$L$2:$L$334,"B-",Data!$D$2:$D$334,"SME") -> 21 | I19: =SUMPRODUCT(COUNTIFS(Data!$L$2:$L$334,{"A+","A","B+","B","B-","C"},Data!$D$2:$D$334,"SME")) -> 141 | J19: =IF(I19=0,"",H19/I19) -> 0.14893617 | K19: =IF(OR(D19="",J19=""),"",(J19-D19)*100) -> 5.7333117
A20: BCI | B20: =COUNTIFS(Data!$J$2:$J$334,"B-",Data!$D$2:$D$334,"BCI") -> 0 | C20: =SUMPRODUCT(COUNTIFS(Data!$J$2:$J$334,{"A+","A","B+","B","B-","C"},Data!$D$2:$D$334,"BCI")) -> 4 | D20: =IF(C20=0,"",B20/C20) -> 0 | E20: =COUNTIFS(Data!$K$2:$K$334,"B-",Data!$D$2:$D$334,"BCI") -> 0 | F20: =SUMPRODUCT(COUNTIFS(Data!$K$2:$K$334,{"A+","A","B+","B","B-","C"},Data!$D$2:$D$334,"BCI")) -> 3 | G20: =IF(F20=0,"",E20/F20) -> 0 | H20: =COUNTIFS(Data!$L$2:$L$334,"B-",Data!$D$2:$D$334,"BCI") -> 1 | I20: =SUMPRODUCT(COUNTIFS(Data!$L$2:$L$334,{"A+","A","B+","B","B-","C"},Data!$D$2:$D$334,"BCI")) -> 3 | J20: =IF(I20=0,"",H20/I20) -> 0.33333333 | K20: =IF(OR(D20="",J20=""),"",(J20-D20)*100) -> 33.333333
A22: Region × Segment
A23: Region × Segment | B23: T8 | E23: T9 | H23: T10 MTD | K23: Δ %B- T10 vs T8
B24: #B- | C24: #Graded | D24: %B- | E24: #B- | F24: #Graded | G24: %B- | H24: #B- | I24: #Graded | J24: %B- | K24: (điểm %)
A25: North-FS | B25: =COUNTIFS(Data!$J$2:$J$334,"B-",Data!$C$2:$C$334,"North",Data!$D$2:$D$334,"FS") -> 9 | C25: =SUMPRODUCT(COUNTIFS(Data!$J$2:$J$334,{"A+","A","B+","B","B-","C"},Data!$C$2:$C$334,"North",Data!$D$2:$D$334,"FS")) -> 74 | D25: =IF(C25=0,"",B25/C25) -> 0.12162162 | E25: =COUNTIFS(Data!$K$2:$K$334,"B-",Data!$C$2:$C$334,"North",Data!$D$2:$D$334,"FS") -> 5 | F25: =SUMPRODUCT(COUNTIFS(Data!$K$2:$K$334,{"A+","A","B+","B","B-","C"},Data!$C$2:$C$334,"North",Data!$D$2:$D$334,"FS")) -> 75 | G25: =IF(F25=0,"",E25/F25) -> 0.066666667 | H25: =COUNTIFS(Data!$L$2:$L$334,"B-",Data!$C$2:$C$334,"North",Data!$D$2:$D$334,"FS") -> 2 | I25: =SUMPRODUCT(COUNTIFS(Data!$L$2:$L$334,{"A+","A","B+","B","B-","C"},Data!$C$2:$C$334,"North",Data!$D$2:$D$334,"FS")) -> 70 | J25: =IF(I25=0,"",H25/I25) -> 0.028571429 | K25: =IF(OR(D25="",J25=""),"",(J25-D25)*100) -> -9.3050193
A26: North-SME | B26: =COUNTIFS(Data!$J$2:$J$334,"B-",Data!$C$2:$C$334,"North",Data!$D$2:$D$334,"SME") -> 8 | C26: =SUMPRODUCT(COUNTIFS(Data!$J$2:$J$334,{"A+","A","B+","B","B-","C"},Data!$C$2:$C$334,"North",Data!$D$2:$D$334,"SME")) -> 69 | D26: =IF(C26=0,"",B26/C26) -> 0.11594203 | E26: =COUNTIFS(Data!$K$2:$K$334,"B-",Data!$C$2:$C$334,"North",Data!$D$2:$D$334,"SME") -> 8 | F26: =SUMPRODUCT(COUNTIFS(Data!$K$2:$K$334,{"A+","A","B+","B","B-","C"},Data!$C$2:$C$334,"North",Data!$D$2:$D$334,"SME")) -> 75 | G26: =IF(F26=0,"",E26/F26) -> 0.10666667 | H26: =COUNTIFS(Data!$L$2:$L$334,"B-",Data!$C$2:$C$334,"North",Data!$D$2:$D$334,"SME") -> 9 | I26: =SUMPRODUCT(COUNTIFS(Data!$L$2:$L$334,{"A+","A","B+","B","B-","C"},Data!$C$2:$C$334,"North",Data!$D$2:$D$334,"SME")) -> 76 | J26: =IF(I26=0,"",H26/I26) -> 0.11842105 | K26: =IF(OR(D26="",J26=""),"",(J26-D26)*100) -> 0.24790236
A27: South-FS | B27: =COUNTIFS(Data!$J$2:$J$334,"B-",Data!$C$2:$C$334,"South",Data!$D$2:$D$334,"FS") -> 1 | C27: =SUMPRODUCT(COUNTIFS(Data!$J$2:$J$334,{"A+","A","B+","B","B-","C"},Data!$C$2:$C$334,"South",Data!$D$2:$D$334,"FS")) -> 22 | D27: =IF(C27=0,"",B27/C27) -> 0.045454545 | E27: =COUNTIFS(Data!$K$2:$K$334,"B-",Data!$C$2:$C$334,"South",Data!$D$2:$D$334,"FS") -> 2 | F27: =SUMPRODUCT(COUNTIFS(Data!$K$2:$K$334,{"A+","A","B+","B","B-","C"},Data!$C$2:$C$334,"South",Data!$D$2:$D$334,"FS")) -> 34 | G27: =IF(F27=0,"",E27/F27) -> 0.058823529 | H27: =COUNTIFS(Data!$L$2:$L$334,"B-",Data!$C$2:$C$334,"South",Data!$D$2:$D$334,"FS") -> 1 | I27: =SUMPRODUCT(COUNTIFS(Data!$L$2:$L$334,{"A+","A","B+","B","B-","C"},Data!$C$2:$C$334,"South",Data!$D$2:$D$334,"FS")) -> 29 | J27: =IF(I27=0,"",H27/I27) -> 0.034482759 | K27: =IF(OR(D27="",J27=""),"",(J27-D27)*100) -> -1.0971787
A28: South-SME | B28: =COUNTIFS(Data!$J$2:$J$334,"B-",Data!$C$2:$C$334,"South",Data!$D$2:$D$334,"SME") -> 4 | C28: =SUMPRODUCT(COUNTIFS(Data!$J$2:$J$334,{"A+","A","B+","B","B-","C"},Data!$C$2:$C$334,"South",Data!$D$2:$D$334,"SME")) -> 62 | D28: =IF(C28=0,"",B28/C28) -> 0.064516129 | E28: =COUNTIFS(Data!$K$2:$K$334,"B-",Data!$C$2:$C$334,"South",Data!$D$2:$D$334,"SME") -> 8 | F28: =SUMPRODUCT(COUNTIFS(Data!$K$2:$K$334,{"A+","A","B+","B","B-","C"},Data!$C$2:$C$334,"South",Data!$D$2:$D$334,"SME")) -> 62 | G28: =IF(F28=0,"",E28/F28) -> 0.12903226 | H28: =COUNTIFS(Data!$L$2:$L$334,"B-",Data!$C$2:$C$334,"South",Data!$D$2:$D$334,"SME") -> 12 | I28: =SUMPRODUCT(COUNTIFS(Data!$L$2:$L$334,{"A+","A","B+","B","B-","C"},Data!$C$2:$C$334,"South",Data!$D$2:$D$334,"SME")) -> 65 | J28: =IF(I28=0,"",H28/I28) -> 0.18461538 | K28: =IF(OR(D28="",J28=""),"",(J28-D28)*100) -> 12.009926
A29: South-BCI | B29: =COUNTIFS(Data!$J$2:$J$334,"B-",Data!$C$2:$C$334,"South",Data!$D$2:$D$334,"BCI") -> 0 | C29: =SUMPRODUCT(COUNTIFS(Data!$J$2:$J$334,{"A+","A","B+","B","B-","C"},Data!$C$2:$C$334,"South",Data!$D$2:$D$334,"BCI")) -> 4 | D29: =IF(C29=0,"",B29/C29) -> 0 | E29: =COUNTIFS(Data!$K$2:$K$334,"B-",Data!$C$2:$C$334,"South",Data!$D$2:$D$334,"BCI") -> 0 | F29: =SUMPRODUCT(COUNTIFS(Data!$K$2:$K$334,{"A+","A","B+","B","B-","C"},Data!$C$2:$C$334,"South",Data!$D$2:$D$334,"BCI")) -> 3 | G29: =IF(F29=0,"",E29/F29) -> 0 | H29: =COUNTIFS(Data!$L$2:$L$334,"B-",Data!$C$2:$C$334,"South",Data!$D$2:$D$334,"BCI") -> 1 | I29: =SUMPRODUCT(COUNTIFS(Data!$L$2:$L$334,{"A+","A","B+","B","B-","C"},Data!$C$2:$C$334,"South",Data!$D$2:$D$334,"BCI")) -> 3 | J29: =IF(I29=0,"",H29/I29) -> 0.33333333 | K29: =IF(OR(D29="",J29=""),"",(J29-D29)*100) -> 33.333333
A31: Team
A32: Team | B32: T8 | E32: T9 | H32: T10 MTD | K32: Δ %B- T10 vs T8
B33: #B- | C33: #Graded | D33: %B- | E33: #B- | F33: #Graded | G33: %B- | H33: #B- | I33: #Graded | J33: %B- | K33: (điểm %)
A34: HN-F1 | B34: =COUNTIFS(Data!$J$2:$J$334,"B-",Data!$B$2:$B$334,"HN-F1") -> 0 | C34: =SUMPRODUCT(COUNTIFS(Data!$J$2:$J$334,{"A+","A","B+","B","B-","C"},Data!$B$2:$B$334,"HN-F1")) -> 2 | D34: =IF(C34=0,"",B34/C34) -> 0 | E34: =COUNTIFS(Data!$K$2:$K$334,"B-",Data!$B$2:$B$334,"HN-F1") -> 0 | F34: =SUMPRODUCT(COUNTIFS(Data!$K$2:$K$334,{"A+","A","B+","B","B-","C"},Data!$B$2:$B$334,"HN-F1")) -> 5 | G34: =IF(F34=0,"",E34/F34) -> 0 | H34: =COUNTIFS(Data!$L$2:$L$334,"B-",Data!$B$2:$B$334,"HN-F1") -> 0 | I34: =SUMPRODUCT(COUNTIFS(Data!$L$2:$L$334,{"A+","A","B+","B","B-","C"},Data!$B$2:$B$334,"HN-F1")) -> 4 | J34: =IF(I34=0,"",H34/I34) -> 0 | K34: =IF(OR(D34="",J34=""),"",(J34-D34)*100) -> 0
A35: HN-F2 | B35: =COUNTIFS(Data!$J$2:$J$334,"B-",Data!$B$2:$B$334,"HN-F2") -> 3 | C35: =SUMPRODUCT(COUNTIFS(Data!$J$2:$J$334,{"A+","A","B+","B","B-","C"},Data!$B$2:$B$334,"HN-F2")) -> 10 | D35: =IF(C35=0,"",B35/C35) -> 0.3 | E35: =COUNTIFS(Data!$K$2:$K$334,"B-",Data!$B$2:$B$334,"HN-F2") -> 0 | F35: =SUMPRODUCT(COUNTIFS(Data!$K$2:$K$334,{"A+","A","B+","B","B-","C"},Data!$B$2:$B$334,"HN-F2")) -> 9 | G35: =IF(F35=0,"",E35/F35) -> 0 | H35: =COUNTIFS(Data!$L$2:$L$334,"B-",Data!$B$2:$B$334,"HN-F2") -> 1 | I35: =SUMPRODUCT(COUNTIFS(Data!$L$2:$L$334,{"A+","A","B+","B","B-","C"},Data!$B$2:$B$334,"HN-F2")) -> 13 | J35: =IF(I35=0,"",H35/I35) -> 0.076923077 | K35: =IF(OR(D35="",J35=""),"",(J35-D35)*100) -> -22.307692
A36: HN-F3 | B36: =COUNTIFS(Data!$J$2:$J$334,"B-",Data!$B$2:$B$334,"HN-F3") -> 0 | C36: =SUMPRODUCT(COUNTIFS(Data!$J$2:$J$334,{"A+","A","B+","B","B-","C"},Data!$B$2:$B$334,"HN-F3")) -> 13 | D36: =IF(C36=0,"",B36/C36) -> 0 | E36: =COUNTIFS(Data!$K$2:$K$334,"B-",Data!$B$2:$B$334,"HN-F3") -> 1 | F36: =SUMPRODUCT(COUNTIFS(Data!$K$2:$K$334,{"A+","A","B+","B","B-","C"},Data!$B$2:$B$334,"HN-F3")) -> 11 | G36: =IF(F36=0,"",E36/F36) -> 0.090909091 | H36: =COUNTIFS(Data!$L$2:$L$334,"B-",Data!$B$2:$B$334,"HN-F3") -> 0 | I36: =SUMPRODUCT(COUNTIFS(Data!$L$2:$L$334,{"A+","A","B+","B","B-","C"},Data!$B$2:$B$334,"HN-F3")) -> 11 | J36: =IF(I36=0,"",H36/I36) -> 0 | K36: =IF(OR(D36="",J36=""),"",(J36-D36)*100) -> 0
A37: HN-F4 | B37: =COUNTIFS(Data!$J$2:$J$334,"B-",Data!$B$2:$B$334,"HN-F4") -> 2 | C37: =SUMPRODUCT(COUNTIFS(Data!$J$2:$J$334,{"A+","A","B+","B","B-","C"},Data!$B$2:$B$334,"HN-F4")) -> 13 | D37: =IF(C37=0,"",B37/C37) -> 0.15384615 | E37: =COUNTIFS(Data!$K$2:$K$334,"B-",Data!$B$2:$B$334,"HN-F4") -> 2 | F37: =SUMPRODUCT(COUNTIFS(Data!$K$2:$K$334,{"A+","A","B+","B","B-","C"},Data!$B$2:$B$334,"HN-F4")) -> 13 | G37: =IF(F37=0,"",E37/F37) -> 0.15384615 | H37: =COUNTIFS(Data!$L$2:$L$334,"B-",Data!$B$2:$B$334,"HN-F4") -> 0 | I37: =SUMPRODUCT(COUNTIFS(Data!$L$2:$L$334,{"A+","A","B+","B","B-","C"},Data!$B$2:$B$334,"HN-F4")) -> 12 | J37: =IF(I37=0,"",H37/I37) -> 0 | K37: =IF(OR(D37="",J37=""),"",(J37-D37)*100) -> -15.384615
A38: HN-F5 | B38: =COUNTIFS(Data!$J$2:$J$334,"B-",Data!$B$2:$B$334,"HN-F5") -> 1 | C38: =SUMPRODUCT(COUNTIFS(Data!$J$2:$J$334,{"A+","A","B+","B","B-","C"},Data!$B$2:$B$334,"HN-F5")) -> 12 | D38: =IF(C38=0,"",B38/C38) -> 0.083333333 | E38: =COUNTIFS(Data!$K$2:$K$334,"B-",Data!$B$2:$B$334,"HN-F5") -> 1 | F38: =SUMPRODUCT(COUNTIFS(Data!$K$2:$K$334,{"A+","A","B+","B","B-","C"},Data!$B$2:$B$334,"HN-F5")) -> 12 | G38: =IF(F38=0,"",E38/F38) -> 0.083333333 | H38: =COUNTIFS(Data!$L$2:$L$334,"B-",Data!$B$2:$B$334,"HN-F5") -> 0 | I38: =SUMPRODUCT(COUNTIFS(Data!$L$2:$L$334,{"A+","A","B+","B","B-","C"},Data!$B$2:$B$334,"HN-F5")) -> 8 | J38: =IF(I38=0,"",H38/I38) -> 0 | K38: =IF(OR(D38="",J38=""),"",(J38-D38)*100) -> -8.3333333
A39: HN-F6 | B39: =COUNTIFS(Data!$J$2:$J$334,"B-",Data!$B$2:$B$334,"HN-F6") -> 0 | C39: =SUMPRODUCT(COUNTIFS(Data!$J$2:$J$334,{"A+","A","B+","B","B-","C"},Data!$B$2:$B$334,"HN-F6")) -> 11 | D39: =IF(C39=0,"",B39/C39) -> 0 | E39: =COUNTIFS(Data!$K$2:$K$334,"B-",Data!$B$2:$B$334,"HN-F6") -> 0 | F39: =SUMPRODUCT(COUNTIFS(Data!$K$2:$K$334,{"A+","A","B+","B","B-","C"},Data!$B$2:$B$334,"HN-F6")) -> 12 | G39: =IF(F39=0,"",E39/F39) -> 0 | H39: =COUNTIFS(Data!$L$2:$L$334,"B-",Data!$B$2:$B$334,"HN-F6") -> 0 | I39: =SUMPRODUCT(COUNTIFS(Data!$L$2:$L$334,{"A+","A","B+","B","B-","C"},Data!$B$2:$B$334,"HN-F6")) -> 9 | J39: =IF(I39=0,"",H39/I39) -> 0 | K39: =IF(OR(D39="",J39=""),"",(J39-D39)*100) -> 0
A40: HN-FX | B40: =COUNTIFS(Data!$J$2:$J$334,"B-",Data!$B$2:$B$334,"HN-FX") -> 1 | C40: =SUMPRODUCT(COUNTIFS(Data!$J$2:$J$334,{"A+","A","B+","B","B-","C"},Data!$B$2:$B$334,"HN-FX")) -> 7 | D40: =IF(C40=0,"",B40/C40) -> 0.14285714 | E40: =COUNTIFS(Data!$K$2:$K$334,"B-",Data!$B$2:$B$334,"HN-FX") -> 1 | F40: =SUMPRODUCT(COUNTIFS(Data!$K$2:$K$334,{"A+","A","B+","B","B-","C"},Data!$B$2:$B$334,"HN-FX")) -> 7 | G40: =IF(F40=0,"",E40/F40) -> 0.14285714 | H40: =COUNTIFS(Data!$L$2:$L$334,"B-",Data!$B$2:$B$334,"HN-FX") -> 1 | I40: =SUMPRODUCT(COUNTIFS(Data!$L$2:$L$334,{"A+","A","B+","B","B-","C"},Data!$B$2:$B$334,"HN-FX")) -> 7 | J40: =IF(I40=0,"",H40/I40) -> 0.14285714 | K40: =IF(OR(D40="",J40=""),"",(J40-D40)*100) -> 0
A41: HN1 | B41: =COUNTIFS(Data!$J$2:$J$334,"B-",Data!$B$2:$B$334,"HN1") -> 2 | C41: =SUMPRODUCT(COUNTIFS(Data!$J$2:$J$334,{"A+","A","B+","B","B-","C"},Data!$B$2:$B$334,"HN1")) -> 13 | D41: =IF(C41=0,"",B41/C41) -> 0.15384615 | E41: =COUNTIFS(Data!$K$2:$K$334,"B-",Data!$B$2:$B$334,"HN1") -> 1 | F41: =SUMPRODUCT(COUNTIFS(Data!$K$2:$K$334,{"A+","A","B+","B","B-","C"},Data!$B$2:$B$334,"HN1")) -> 13 | G41: =IF(F41=0,"",E41/F41) -> 0.076923077 | H41: =COUNTIFS(Data!$L$2:$L$334,"B-",Data!$B$2:$B$334,"HN1") -> 2 | I41: =SUMPRODUCT(COUNTIFS(Data!$L$2:$L$334,{"A+","A","B+","B","B-","C"},Data!$B$2:$B$334,"HN1")) -> 13 | J41: =IF(I41=0,"",H41/I41) -> 0.15384615 | K41: =IF(OR(D41="",J41=""),"",(J41-D41)*100) -> 0
A42: HN2 | B42: =COUNTIFS(Data!$J$2:$J$334,"B-",Data!$B$2:$B$334,"HN2") -> 2 | C42: =SUMPRODUCT(COUNTIFS(Data!$J$2:$J$334,{"A+","A","B+","B","B-","C"},Data!$B$2:$B$334,"HN2")) -> 10 | D42: =IF(C42=0,"",B42/C42) -> 0.2 | E42: =COUNTIFS(Data!$K$2:$K$334,"B-",Data!$B$2:$B$334,"HN2") -> 2 | F42: =SUMPRODUCT(COUNTIFS(Data!$K$2:$K$334,{"A+","A","B+","B","B-","C"},Data!$B$2:$B$334,"HN2")) -> 10 | G42: =IF(F42=0,"",E42/F42) -> 0.2 | H42: =COUNTIFS(Data!$L$2:$L$334,"B-",Data!$B$2:$B$334,"HN2") -> 0 | I42: =SUMPRODUCT(COUNTIFS(Data!$L$2:$L$334,{"A+","A","B+","B","B-","C"},Data!$B$2:$B$334,"HN2")) -> 11 | J42: =IF(I42=0,"",H42/I42) -> 0 | K42: =IF(OR(D42="",J42=""),"",(J42-D42)*100) -> -20
A43: HN3 | B43: =COUNTIFS(Data!$J$2:$J$334,"B-",Data!$B$2:$B$334,"HN3") -> 1 | C43: =SUMPRODUCT(COUNTIFS(Data!$J$2:$J$334,{"A+","A","B+","B","B-","C"},Data!$B$2:$B$334,"HN3")) -> 12 | D43: =IF(C43=0,"",B43/C43) -> 0.083333333 | E43: =COUNTIFS(Data!$K$2:$K$334,"B-",Data!$B$2:$B$334,"HN3") -> 2 | F43: =SUMPRODUCT(COUNTIFS(Data!$K$2:$K$334,{"A+","A","B+","B","B-","C"},Data!$B$2:$B$334,"HN3")) -> 13 | G43: =IF(F43=0,"",E43/F43) -> 0.15384615 | H43: =COUNTIFS(Data!$L$2:$L$334,"B-",Data!$B$2:$B$334,"HN3") -> 2 | I43: =SUMPRODUCT(COUNTIFS(Data!$L$2:$L$334,{"A+","A","B+","B","B-","C"},Data!$B$2:$B$334,"HN3")) -> 14 | J43: =IF(I43=0,"",H43/I43) -> 0.14285714 | K43: =IF(OR(D43="",J43=""),"",(J43-D43)*100) -> 5.952381
A44: HN4 | B44: =COUNTIFS(Data!$J$2:$J$334,"B-",Data!$B$2:$B$334,"HN4") -> 0 | C44: =SUMPRODUCT(COUNTIFS(Data!$J$2:$J$334,{"A+","A","B+","B","B-","C"},Data!$B$2:$B$334,"HN4")) -> 10 | D44: =IF(C44=0,"",B44/C44) -> 0 | E44: =COUNTIFS(Data!$K$2:$K$334,"B-",Data!$B$2:$B$334,"HN4") -> 1 | F44: =SUMPRODUCT(COUNTIFS(Data!$K$2:$K$334,{"A+","A","B+","B","B-","C"},Data!$B$2:$B$334,"HN4")) -> 12 | G44: =IF(F44=0,"",E44/F44) -> 0.083333333 | H44: =COUNTIFS(Data!$L$2:$L$334,"B-",Data!$B$2:$B$334,"HN4") -> 1 | I44: =SUMPRODUCT(COUNTIFS(Data!$L$2:$L$334,{"A+","A","B+","B","B-","C"},Data!$B$2:$B$334,"HN4")) -> 11 | J44: =IF(I44=0,"",H44/I44) -> 0.090909091 | K44: =IF(OR(D44="",J44=""),"",(J44-D44)*100) -> 9.0909091
A45: HN5 | B45: =COUNTIFS(Data!$J$2:$J$334,"B-",Data!$B$2:$B$334,"HN5") -> 1 | C45: =SUMPRODUCT(COUNTIFS(Data!$J$2:$J$334,{"A+","A","B+","B","B-","C"},Data!$B$2:$B$334,"HN5")) -> 12 | D45: =IF(C45=0,"",B45/C45) -> 0.083333333 | E45: =COUNTIFS(Data!$K$2:$K$334,"B-",Data!$B$2:$B$334,"HN5") -> 1 | F45: =SUMPRODUCT(COUNTIFS(Data!$K$2:$K$334,{"A+","A","B+","B","B-","C"},Data!$B$2:$B$334,"HN5")) -> 13 | G45: =IF(F45=0,"",E45/F45) -> 0.076923077 | H45: =COUNTIFS(Data!$L$2:$L$334,"B-",Data!$B$2:$B$334,"HN5") -> 2 | I45: =SUMPRODUCT(COUNTIFS(Data!$L$2:$L$334,{"A+","A","B+","B","B-","C"},Data!$B$2:$B$334,"HN5")) -> 13 | J45: =IF(I45=0,"",H45/I45) -> 0.15384615 | K45: =IF(OR(D45="",J45=""),"",(J45-D45)*100) -> 7.0512821
...

Sheet Summary MOB3+
A1: Tỷ lệ BD Grade B- — T8 / T9 / T10 MTD (15/10/2026) — chỉ BD MOB3+
A2: %B- = #B- ÷ #BD có grade hợp lệ (A+/A/B+/B/B-/C) trong tháng. Loại grade "-" (MOB0) và ô trống (chưa vào / đã nghỉ). Công thức COUNTIFS trỏ về sheet Data.
A4: Total
A5: Total | B5: T8 | E5: T9 | H5: T10 MTD | K5: Δ %B- T10 vs T8
B6: #B- | C6: #Graded | D6: %B- | E6: #B- | F6: #Graded | G6: %B- | H6: #B- | I6: #Graded | J6: %B- | K6: (điểm %)
A7: Total | B7: =COUNTIFS(Data!$J$2:$J$334,"B-",Data!$G$2:$G$334,"MOB3+") -> 18 | C7: =SUMPRODUCT(COUNTIFS(Data!$J$2:$J$334,{"A+","A","B+","B","B-","C"},Data!$G$2:$G$334,"MOB3+")) -> 179 | D7: =IF(C7=0,"",B7/C7) -> 0.10055866 | E7: =COUNTIFS(Data!$K$2:$K$334,"B-",Data!$H$2:$H$334,"MOB3+") -> 21 | F7: =SUMPRODUCT(COUNTIFS(Data!$K$2:$K$334,{"A+","A","B+","B","B-","C"},Data!$H$2:$H$334,"MOB3+")) -> 189 | G7: =IF(F7=0,"",E7/F7) -> 0.11111111 | H7: =COUNTIFS(Data!$L$2:$L$334,"B-",Data!$I$2:$I$334,"MOB3+") -> 21 | I7: =SUMPRODUCT(COUNTIFS(Data!$L$2:$L$334,{"A+","A","B+","B","B-","C"},Data!$I$2:$I$334,"MOB3+")) -> 182 | J7: =IF(I7=0,"",H7/I7) -> 0.11538462 | K7: =IF(OR(D7="",J7=""),"",(J7-D7)*100) -> 1.4825956
A9: Region
A10: Region | B10: T8 | E10: T9 | H10: T10 MTD | K10: Δ %B- T10 vs T8
B11: #B- | C11: #Graded | D11: %B- | E11: #B- | F11: #Graded | G11: %B- | H11: #B- | I11: #Graded | J11: %B- | K11: (điểm %)
A12: North | B12: =COUNTIFS(Data!$J$2:$J$334,"B-",Data!$C$2:$C$334,"North",Data!$G$2:$G$334,"MOB3+") -> 15 | C12: =SUMPRODUCT(COUNTIFS(Data!$J$2:$J$334,{"A+","A","B+","B","B-","C"},Data!$C$2:$C$334,"North",Data!$G$2:$G$334,"MOB3+")) -> 119 | D12: =IF(C12=0,"",B12/C12) -> 0.12605042 | E12: =COUNTIFS(Data!$K$2:$K$334,"B-",Data!$C$2:$C$334,"North",Data!$H$2:$H$334,"MOB3+") -> 12 | F12: =SUMPRODUCT(COUNTIFS(Data!$K$2:$K$334,{"A+","A","B+","B","B-","C"},Data!$C$2:$C$334,"North",Data!$H$2:$H$334,"MOB3+")) -> 130 | G12: =IF(F12=0,"",E12/F12) -> 0.092307692 | H12: =COUNTIFS(Data!$L$2:$L$334,"B-",Data!$C$2:$C$334,"North",Data!$I$2:$I$334,"MOB3+") -> 10 | I12: =SUMPRODUCT(COUNTIFS(Data!$L$2:$L$334,{"A+","A","B+","B","B-","C"},Data!$C$2:$C$334,"North",Data!$I$2:$I$334,"MOB3+")) -> 118 | J12: =IF(I12=0,"",H12/I12) -> 0.084745763 | K12: =IF(OR(D12="",J12=""),"",(J12-D12)*100) -> -4.1304657
A13: South | B13: =COUNTIFS(Data!$J$2:$J$334,"B-",Data!$C$2:$C$334,"South",Data!$G$2:$G$334,"MOB3+") -> 3 | C13: =SUMPRODUCT(COUNTIFS(Data!$J$2:$J$334,{"A+","A","B+","B","B-","C"},Data!$C$2:$C$334,"South",Data!$G$2:$G$334,"MOB3+")) -> 60 | D13: =IF(C13=0,"",B13/C13) -> 0.05 | E13: =COUNTIFS(Data!$K$2:$K$334,"B-",Data!$C$2:$C$334,"South",Data!$H$2:$H$334,"MOB3+") -> 9 | F13: =SUMPRODUCT(COUNTIFS(Data!$K$2:$K$334,{"A+","A","B+","B","B-","C"},Data!$C$2:$C$334,"South",Data!$H$2:$H$334,"MOB3+")) -> 59 | G13: =IF(F13=0,"",E13/F13) -> 0.15254237 | H13: =COUNTIFS(Data!$L$2:$L$334,"B-",Data!$C$2:$C$334,"South",Data!$I$2:$I$334,"MOB3+") -> 11 | I13: =SUMPRODUCT(COUNTIFS(Data!$L$2:$L$334,{"A+","A","B+","B","B-","C"},Data!$C$2:$C$334,"South",Data!$I$2:$I$334,"MOB3+")) -> 64 | J13: =IF(I13=0,"",H13/I13) -> 0.171875 | K13: =IF(OR(D13="",J13=""),"",(J13-D13)*100) -> 12.1875
A15: Segment
A16: Segment | B16: T8 | E16: T9 | H16: T10 MTD | K16: Δ %B- T10 vs T8
B17: #B- | C17: #Graded | D17: %B- | E17: #B- | F17: #Graded | G17: %B- | H17: #B- | I17: #Graded | J17: %B- | K17: (điểm %)
A18: FS | B18: =COUNTIFS(Data!$J$2:$J$334,"B-",Data!$D$2:$D$334,"FS",Data!$G$2:$G$334,"MOB3+") -> 10 | C18: =SUMPRODUCT(COUNTIFS(Data!$J$2:$J$334,{"A+","A","B+","B","B-","C"},Data!$D$2:$D$334,"FS",Data!$G$2:$G$334,"MOB3+")) -> 62 | D18: =IF(C18=0,"",B18/C18) -> 0.16129032 | E18: =COUNTIFS(Data!$K$2:$K$334,"B-",Data!$D$2:$D$334,"FS",Data!$H$2:$H$334,"MOB3+") -> 7 | F18: =SUMPRODUCT(COUNTIFS(Data!$K$2:$K$334,{"A+","A","B+","B","B-","C"},Data!$D$2:$D$334,"FS",Data!$H$2:$H$334,"MOB3+")) -> 75 | G18: =IF(F18=0,"",E18/F18) -> 0.093333333 | H18: =COUNTIFS(Data!$L$2:$L$334,"B-",Data!$D$2:$D$334,"FS",Data!$I$2:$I$334,"MOB3+") -> 3 | I18: =SUMPRODUCT(COUNTIFS(Data!$L$2:$L$334,{"A+","A","B+","B","B-","C"},Data!$D$2:$D$334,"FS",Data!$I$2:$I$334,"MOB3+")) -> 62 | J18: =IF(I18=0,"",H18/I18) -> 0.048387097 | K18: =IF(OR(D18="",J18=""),"",(J18-D18)*100) -> -11.290323
A19: SME | B19: =COUNTIFS(Data!$J$2:$J$334,"B-",Data!$D$2:$D$334,"SME",Data!$G$2:$G$334,"MOB3+") -> 8 | C19: =SUMPRODUCT(COUNTIFS(Data!$J$2:$J$334,{"A+","A","B+","B","B-","C"},Data!$D$2:$D$334,"SME",Data!$G$2:$G$334,"MOB3+")) -> 114 | D19: =IF(C19=0,"",B19/C19) -> 0.070175439 | E19: =COUNTIFS(Data!$K$2:$K$334,"B-",Data!$D$2:$D$334,"SME",Data!$H$2:$H$334,"MOB3+") -> 14 | F19: =SUMPRODUCT(COUNTIFS(Data!$K$2:$K$334,{"A+","A","B+","B","B-","C"},Data!$D$2:$D$334,"SME",Data!$H$2:$H$334,"MOB3+")) -> 113 | G19: =IF(F19=0,"",E19/F19) -> 0.12389381 | H19: =COUNTIFS(Data!$L$2:$L$334,"B-",Data!$D$2:$D$334,"SME",Data!$I$2:$I$334,"MOB3+") -> 17 | I19: =SUMPRODUCT(COUNTIFS(Data!$L$2:$L$334,{"A+","A","B+","B","B-","C"},Data!$D$2:$D$334,"SME",Data!$I$2:$I$334,"MOB3+")) -> 118 | J19: =IF(I19=0,"",H19/I19) -> 0.1440678 | K19: =IF(OR(D19="",J19=""),"",(J19-D19)*100) -> 7.3892358
A20: BCI | B20: =COUNTIFS(Data!$J$2:$J$334,"B-",Data!$D$2:$D$334,"BCI",Data!$G$2:$G$334,"MOB3+") -> 0 | C20: =SUMPRODUCT(COUNTIFS(Data!$J$2:$J$334,{"A+","A","B+","B","B-","C"},Data!$D$2:$D$334,"BCI",Data!$G$2:$G$334,"MOB3+")) -> 3 | D20: =IF(C20=0,"",B20/C20) -> 0 | E20: =COUNTIFS(Data!$K$2:$K$334,"B-",Data!$D$2:$D$334,"BCI",Data!$H$2:$H$334,"MOB3+") -> 0 | F20: =SUMPRODUCT(COUNTIFS(Data!$K$2:$K$334,{"A+","A","B+","B","B-","C"},Data!$D$2:$D$334,"BCI",Data!$H$2:$H$334,"MOB3+")) -> 1 | G20: =IF(F20=0,"",E20/F20) -> 0 | H20: =COUNTIFS(Data!$L$2:$L$334,"B-",Data!$D$2:$D$334,"BCI",Data!$I$2:$I$334,"MOB3+") -> 1 | I20: =SUMPRODUCT(COUNTIFS(Data!$L$2:$L$334,{"A+","A","B+","B","B-","C"},Data!$D$2:$D$334,"BCI",Data!$I$2:$I$334,"MOB3+")) -> 2 | J20: =IF(I20=0,"",H20/I20) -> 0.5 | K20: =IF(OR(D20="",J20=""),"",(J20-D20)*100) -> 50
A22: Region × Segment
A23: Region × Segment | B23: T8 | E23: T9 | H23: T10 MTD | K23: Δ %B- T10 vs T8
B24: #B- | C24: #Graded | D24: %B- | E24: #B- | F24: #Graded | G24: %B- | H24: #B- | I24: #Graded | J24: %B- | K24: (điểm %)
A25: North-FS | B25: =COUNTIFS(Data!$J$2:$J$334,"B-",Data!$C$2:$C$334,"North",Data!$D$2:$D$334,"FS",Data!$G$2:$G$334,"MOB3+") -> 9 | C25: =SUMPRODUCT(COUNTIFS(Data!$J$2:$J$334,{"A+","A","B+","B","B-","C"},Data!$C$2:$C$334,"North",Data!$D$2:$D$334,"FS",Data!$G$2:$G$334,"MOB3+")) -> 57 | D25: =IF(C25=0,"",B25/C25) -> 0.15789474 | E25: =COUNTIFS(Data!$K$2:$K$334,"B-",Data!$C$2:$C$334,"North",Data!$D$2:$D$334,"FS",Data!$H$2:$H$334,"MOB3+") -> 5 | F25: =SUMPRODUCT(COUNTIFS(Data!$K$2:$K$334,{"A+","A","B+","B","B-","C"},Data!$C$2:$C$334,"North",Data!$D$2:$D$334,"FS",Data!$H$2:$H$334,"MOB3+")) -> 65 | G25: =IF(F25=0,"",E25/F25) -> 0.076923077 | H25: =COUNTIFS(Data!$L$2:$L$334,"B-",Data!$C$2:$C$334,"North",Data!$D$2:$D$334,"FS",Data!$I$2:$I$334,"MOB3+") -> 2 | I25: =SUMPRODUCT(COUNTIFS(Data!$L$2:$L$334,{"A+","A","B+","B","B-","C"},Data!$C$2:$C$334,"North",Data!$D$2:$D$334,"FS",Data!$I$2:$I$334,"MOB3+")) -> 51 | J25: =IF(I25=0,"",H25/I25) -> 0.039215686 | K25: =IF(OR(D25="",J25=""),"",(J25-D25)*100) -> -11.867905
A26: North-SME | B26: =COUNTIFS(Data!$J$2:$J$334,"B-",Data!$C$2:$C$334,"North",Data!$D$2:$D$334,"SME",Data!$G$2:$G$334,"MOB3+") -> 6 | C26: =SUMPRODUCT(COUNTIFS(Data!$J$2:$J$334,{"A+","A","B+","B","B-","C"},Data!$C$2:$C$334,"North",Data!$D$2:$D$334,"SME",Data!$G$2:$G$334,"MOB3+")) -> 62 | D26: =IF(C26=0,"",B26/C26) -> 0.096774194 | E26: =COUNTIFS(Data!$K$2:$K$334,"B-",Data!$C$2:$C$334,"North",Data!$D$2:$D$334,"SME",Data!$H$2:$H$334,"MOB3+") -> 7 | F26: =SUMPRODUCT(COUNTIFS(Data!$K$2:$K$334,{"A+","A","B+","B","B-","C"},Data!$C$2:$C$334,"North",Data!$D$2:$D$334,"SME",Data!$H$2:$H$334,"MOB3+")) -> 65 | G26: =IF(F26=0,"",E26/F26) -> 0.10769231 | H26: =COUNTIFS(Data!$L$2:$L$334,"B-",Data!$C$2:$C$334,"North",Data!$D$2:$D$334,"SME",Data!$I$2:$I$334,"MOB3+") -> 8 | I26: =SUMPRODUCT(COUNTIFS(Data!$L$2:$L$334,{"A+","A","B+","B","B-","C"},Data!$C$2:$C$334,"North",Data!$D$2:$D$334,"SME",Data!$I$2:$I$334,"MOB3+")) -> 67 | J26: =IF(I26=0,"",H26/I26) -> 0.11940299 | K26: =IF(OR(D26="",J26=""),"",(J26-D26)*100) -> 2.2628792
A27: South-FS | B27: =COUNTIFS(Data!$J$2:$J$334,"B-",Data!$C$2:$C$334,"South",Data!$D$2:$D$334,"FS",Data!$G$2:$G$334,"MOB3+") -> 1 | C27: =SUMPRODUCT(COUNTIFS(Data!$J$2:$J$334,{"A+","A","B+","B","B-","C"},Data!$C$2:$C$334,"South",Data!$D$2:$D$334,"FS",Data!$G$2:$G$334,"MOB3+")) -> 5 | D27: =IF(C27=0,"",B27/C27) -> 0.2 | E27: =COUNTIFS(Data!$K$2:$K$334,"B-",Data!$C$2:$C$334,"South",Data!$D$2:$D$334,"FS",Data!$H$2:$H$334,"MOB3+") -> 2 | F27: =SUMPRODUCT(COUNTIFS(Data!$K$2:$K$334,{"A+","A","B+","B","B-","C"},Data!$C$2:$C$334,"South",Data!$D$2:$D$334,"FS",Data!$H$2:$H$334,"MOB3+")) -> 10 | G27: =IF(F27=0,"",E27/F27) -> 0.2 | H27: =COUNTIFS(Data!$L$2:$L$334,"B-",Data!$C$2:$C$334,"South",Data!$D$2:$D$334,"FS",Data!$I$2:$I$334,"MOB3+") -> 1 | I27: =SUMPRODUCT(COUNTIFS(Data!$L$2:$L$334,{"A+","A","B+","B","B-","C"},Data!$C$2:$C$334,"South",Data!$D$2:$D$334,"FS",Data!$I$2:$I$334,"MOB3+")) -> 11 | J27: =IF(I27=0,"",H27/I27) -> 0.090909091 | K27: =IF(OR(D27="",J27=""),"",(J27-D27)*100) -> -10.909091
A28: South-SME | B28: =COUNTIFS(Data!$J$2:$J$334,"B-",Data!$C$2:$C$334,"South",Data!$D$2:$D$334,"SME",Data!$G$2:$G$334,"MOB3+") -> 2 | C28: =SUMPRODUCT(COUNTIFS(Data!$J$2:$J$334,{"A+","A","B+","B","B-","C"},Data!$C$2:$C$334,"South",Data!$D$2:$D$334,"SME",Data!$G$2:$G$334,"MOB3+")) -> 52 | D28: =IF(C28=0,"",B28/C28) -> 0.038461538 | E28: =COUNTIFS(Data!$K$2:$K$334,"B-",Data!$C$2:$C$334,"South",Data!$D$2:$D$334,"SME",Data!$H$2:$H$334,"MOB3+") -> 7 | F28: =SUMPRODUCT(COUNTIFS(Data!$K$2:$K$334,{"A+","A","B+","B","B-","C"},Data!$C$2:$C$334,"South",Data!$D$2:$D$334,"SME",Data!$H$2:$H$334,"MOB3+")) -> 48 | G28: =IF(F28=0,"",E28/F28) -> 0.14583333 | H28: =COUNTIFS(Data!$L$2:$L$334,"B-",Data!$C$2:$C$334,"South",Data!$D$2:$D$334,"SME",Data!$I$2:$I$334,"MOB3+") -> 9 | I28: =SUMPRODUCT(COUNTIFS(Data!$L$2:$L$334,{"A+","A","B+","B","B-","C"},Data!$C$2:$C$334,"South",Data!$D$2:$D$334,"SME",Data!$I$2:$I$334,"MOB3+")) -> 51 | J28: =IF(I28=0,"",H28/I28) -> 0.17647059 | K28: =IF(OR(D28="",J28=""),"",(J28-D28)*100) -> 13.800905
A29: South-BCI | B29: =COUNTIFS(Data!$J$2:$J$334,"B-",Data!$C$2:$C$334,"South",Data!$D$2:$D$334,"BCI",Data!$G$2:$G$334,"MOB3+") -> 0 | C29: =SUMPRODUCT(COUNTIFS(Data!$J$2:$J$334,{"A+","A","B+","B","B-","C"},Data!$C$2:$C$334,"South",Data!$D$2:$D$334,"BCI",Data!$G$2:$G$334,"MOB3+")) -> 3 | D29: =IF(C29=0,"",B29/C29) -> 0 | E29: =COUNTIFS(Data!$K$2:$K$334,"B-",Data!$C$2:$C$334,"South",Data!$D$2:$D$334,"BCI",Data!$H$2:$H$334,"MOB3+") -> 0 | F29: =SUMPRODUCT(COUNTIFS(Data!$K$2:$K$334,{"A+","A","B+","B","B-","C"},Data!$C$2:$C$334,"South",Data!$D$2:$D$334,"BCI",Data!$H$2:$H$334,"MOB3+")) -> 1 | G29: =IF(F29=0,"",E29/F29) -> 0 | H29: =COUNTIFS(Data!$L$2:$L$334,"B-",Data!$C$2:$C$334,"South",Data!$D$2:$D$334,"BCI",Data!$I$2:$I$334,"MOB3+") -> 1 | I29: =SUMPRODUCT(COUNTIFS(Data!$L$2:$L$334,{"A+","A","B+","B","B-","C"},Data!$C$2:$C$334,"South",Data!$D$2:$D$334,"BCI",Data!$I$2:$I$334,"MOB3+")) -> 2 | J29: =IF(I29=0,"",H29/I29) -> 0.5 | K29: =IF(OR(D29="",J29=""),"",(J29-D29)*100) -> 50
A31: Team
A32: Team | B32: T8 | E32: T9 | H32: T10 MTD | K32: Δ %B- T10 vs T8
B33: #B- | C33: #Graded | D33: %B- | E33: #B- | F33: #Graded | G33: %B- | H33: #B- | I33: #Graded | J33: %B- | K33: (điểm %)
A34: HN-F1 | B34: =COUNTIFS(Data!$J$2:$J$334,"B-",Data!$B$2:$B$334,"HN-F1",Data!$G$2:$G$334,"MOB3+") -> 0 | C34: =SUMPRODUCT(COUNTIFS(Data!$J$2:$J$334,{"A+","A","B+","B","B-","C"},Data!$B$2:$B$334,"HN-F1",Data!$G$2:$G$334,"MOB3+")) -> 2 | D34: =IF(C34=0,"",B34/C34) -> 0 | E34: =COUNTIFS(Data!$K$2:$K$334,"B-",Data!$B$2:$B$334,"HN-F1",Data!$H$2:$H$334,"MOB3+") -> 0 | F34: =SUMPRODUCT(COUNTIFS(Data!$K$2:$K$334,{"A+","A","B+","B","B-","C"},Data!$B$2:$B$334,"HN-F1",Data!$H$2:$H$334,"MOB3+")) -> 2 | G34: =IF(F34=0,"",E34/F34) -> 0 | H34: =COUNTIFS(Data!$L$2:$L$334,"B-",Data!$B$2:$B$334,"HN-F1",Data!$I$2:$I$334,"MOB3+") -> 0 | I34: =SUMPRODUCT(COUNTIFS(Data!$L$2:$L$334,{"A+","A","B+","B","B-","C"},Data!$B$2:$B$334,"HN-F1",Data!$I$2:$I$334,"MOB3+")) -> 1 | J34: =IF(I34=0,"",H34/I34) -> 0 | K34: =IF(OR(D34="",J34=""),"",(J34-D34)*100) -> 0
A35: HN-F2 | B35: =COUNTIFS(Data!$J$2:$J$334,"B-",Data!$B$2:$B$334,"HN-F2",Data!$G$2:$G$334,"MOB3+") -> 3 | C35: =SUMPRODUCT(COUNTIFS(Data!$J$2:$J$334,{"A+","A","B+","B","B-","C"},Data!$B$2:$B$334,"HN-F2",Data!$G$2:$G$334,"MOB3+")) -> 9 | D35: =IF(C35=0,"",B35/C35) -> 0.33333333 | E35: =COUNTIFS(Data!$K$2:$K$334,"B-",Data!$B$2:$B$334,"HN-F2",Data!$H$2:$H$334,"MOB3+") -> 0 | F35: =SUMPRODUCT(COUNTIFS(Data!$K$2:$K$334,{"A+","A","B+","B","B-","C"},Data!$B$2:$B$334,"HN-F2",Data!$H$2:$H$334,"MOB3+")) -> 9 | G35: =IF(F35=0,"",E35/F35) -> 0 | H35: =COUNTIFS(Data!$L$2:$L$334,"B-",Data!$B$2:$B$334,"HN-F2",Data!$I$2:$I$334,"MOB3+") -> 1 | I35: =SUMPRODUCT(COUNTIFS(Data!$L$2:$L$334,{"A+","A","B+","B","B-","C"},Data!$B$2:$B$334,"HN-F2",Data!$I$2:$I$334,"MOB3+")) -> 9 | J35: =IF(I35=0,"",H35/I35) -> 0.11111111 | K35: =IF(OR(D35="",J35=""),"",(J35-D35)*100) -> -22.222222
A36: HN-F3 | B36: =COUNTIFS(Data!$J$2:$J$334,"B-",Data!$B$2:$B$334,"HN-F3",Data!$G$2:$G$334,"MOB3+") -> 0 | C36: =SUMPRODUCT(COUNTIFS(Data!$J$2:$J$334,{"A+","A","B+","B","B-","C"},Data!$B$2:$B$334,"HN-F3",Data!$G$2:$G$334,"MOB3+")) -> 8 | D36: =IF(C36=0,"",B36/C36) -> 0 | E36: =COUNTIFS(Data!$K$2:$K$334,"B-",Data!$B$2:$B$334,"HN-F3",Data!$H$2:$H$334,"MOB3+") -> 1 | F36: =SUMPRODUCT(COUNTIFS(Data!$K$2:$K$334,{"A+","A","B+","B","B-","C"},Data!$B$2:$B$334,"HN-F3",Data!$H$2:$H$334,"MOB3+")) -> 10 | G36: =IF(F36=0,"",E36/F36) -> 0.1 | H36: =COUNTIFS(Data!$L$2:$L$334,"B-",Data!$B$2:$B$334,"HN-F3",Data!$I$2:$I$334,"MOB3+") -> 0 | I36: =SUMPRODUCT(COUNTIFS(Data!$L$2:$L$334,{"A+","A","B+","B","B-","C"},Data!$B$2:$B$334,"HN-F3",Data!$I$2:$I$334,"MOB3+")) -> 8 | J36: =IF(I36=0,"",H36/I36) -> 0 | K36: =IF(OR(D36="",J36=""),"",(J36-D36)*100) -> 0
A37: HN-F4 | B37: =COUNTIFS(Data!$J$2:$J$334,"B-",Data!$B$2:$B$334,"HN-F4",Data!$G$2:$G$334,"MOB3+") -> 2 | C37: =SUMPRODUCT(COUNTIFS(Data!$J$2:$J$334,{"A+","A","B+","B","B-","C"},Data!$B$2:$B$334,"HN-F4",Data!$G$2:$G$334,"MOB3+")) -> 8 | D37: =IF(C37=0,"",B37/C37) -> 0.25 | E37: =COUNTIFS(Data!$K$2:$K$334,"B-",Data!$B$2:$B$334,"HN-F4",Data!$H$2:$H$334,"MOB3+") -> 2 | F37: =SUMPRODUCT(COUNTIFS(Data!$K$2:$K$334,{"A+","A","B+","B","B-","C"},Data!$B$2:$B$334,"HN-F4",Data!$H$2:$H$334,"MOB3+")) -> 12 | G37: =IF(F37=0,"",E37/F37) -> 0.16666667 | H37: =COUNTIFS(Data!$L$2:$L$334,"B-",Data!$B$2:$B$334,"HN-F4",Data!$I$2:$I$334,"MOB3+") -> 0 | I37: =SUMPRODUCT(COUNTIFS(Data!$L$2:$L$334,{"A+","A","B+","B","B-","C"},Data!$B$2:$B$334,"HN-F4",Data!$I$2:$I$334,"MOB3+")) -> 8 | J37: =IF(I37=0,"",H37/I37) -> 0 | K37: =IF(OR(D37="",J37=""),"",(J37-D37)*100) -> -25
A38: HN-F5 | B38: =COUNTIFS(Data!$J$2:$J$334,"B-",Data!$B$2:$B$334,"HN-F5",Data!$G$2:$G$334,"MOB3+") -> 1 | C38: =SUMPRODUCT(COUNTIFS(Data!$J$2:$J$334,{"A+","A","B+","B","B-","C"},Data!$B$2:$B$334,"HN-F5",Data!$G$2:$G$334,"MOB3+")) -> 7 | D38: =IF(C38=0,"",B38/C38) -> 0.14285714 | E38: =COUNTIFS(Data!$K$2:$K$334,"B-",Data!$B$2:$B$334,"HN-F5",Data!$H$2:$H$334,"MOB3+") -> 1 | F38: =SUMPRODUCT(COUNTIFS(Data!$K$2:$K$334,{"A+","A","B+","B","B-","C"},Data!$B$2:$B$334,"HN-F5",Data!$H$2:$H$334,"MOB3+")) -> 9 | G38: =IF(F38=0,"",E38/F38) -> 0.11111111 | H38: =COUNTIFS(Data!$L$2:$L$334,"B-",Data!$B$2:$B$334,"HN-F5",Data!$I$2:$I$334,"MOB3+") -> 0 | I38: =SUMPRODUCT(COUNTIFS(Data!$L$2:$L$334,{"A+","A","B+","B","B-","C"},Data!$B$2:$B$334,"HN-F5",Data!$I$2:$I$334,"MOB3+")) -> 5 | J38: =IF(I38=0,"",H38/I38) -> 0 | K38: =IF(OR(D38="",J38=""),"",(J38-D38)*100) -> -14.285714
A39: HN-F6 | B39: =COUNTIFS(Data!$J$2:$J$334,"B-",Data!$B$2:$B$334,"HN-F6",Data!$G$2:$G$334,"MOB3+") -> 0 | C39: =SUMPRODUCT(COUNTIFS(Data!$J$2:$J$334,{"A+","A","B+","B","B-","C"},Data!$B$2:$B$334,"HN-F6",Data!$G$2:$G$334,"MOB3+")) -> 10 | D39: =IF(C39=0,"",B39/C39) -> 0 | E39: =COUNTIFS(Data!$K$2:$K$334,"B-",Data!$B$2:$B$334,"HN-F6",Data!$H$2:$H$334,"MOB3+") -> 0 | F39: =SUMPRODUCT(COUNTIFS(Data!$K$2:$K$334,{"A+","A","B+","B","B-","C"},Data!$B$2:$B$334,"HN-F6",Data!$H$2:$H$334,"MOB3+")) -> 10 | G39: =IF(F39=0,"",E39/F39) -> 0 | H39: =COUNTIFS(Data!$L$2:$L$334,"B-",Data!$B$2:$B$334,"HN-F6",Data!$I$2:$I$334,"MOB3+") -> 0 | I39: =SUMPRODUCT(COUNTIFS(Data!$L$2:$L$334,{"A+","A","B+","B","B-","C"},Data!$B$2:$B$334,"HN-F6",Data!$I$2:$I$334,"MOB3+")) -> 7 | J39: =IF(I39=0,"",H39/I39) -> 0 | K39: =IF(OR(D39="",J39=""),"",(J39-D39)*100) -> 0
A40: HN-FX | B40: =COUNTIFS(Data!$J$2:$J$334,"B-",Data!$B$2:$B$334,"HN-FX",Data!$G$2:$G$334,"MOB3+") -> 1 | C40: =SUMPRODUCT(COUNTIFS(Data!$J$2:$J$334,{"A+","A","B+","B","B-","C"},Data!$B$2:$B$334,"HN-FX",Data!$G$2:$G$334,"MOB3+")) -> 7 | D40: =IF(C40=0,"",B40/C40) -> 0.14285714 | E40: =COUNTIFS(Data!$K$2:$K$334,"B-",Data!$B$2:$B$334,"HN-FX",Data!$H$2:$H$334,"MOB3+") -> 1 | F40: =SUMPRODUCT(COUNTIFS(Data!$K$2:$K$334,{"A+","A","B+","B","B-","C"},Data!$B$2:$B$334,"HN-FX",Data!$H$2:$H$334,"MOB3+")) -> 7 | G40: =IF(F40=0,"",E40/F40) -> 0.14285714 | H40: =COUNTIFS(Data!$L$2:$L$334,"B-",Data!$B$2:$B$334,"HN-FX",Data!$I$2:$I$334,"MOB3+") -> 1 | I40: =SUMPRODUCT(COUNTIFS(Data!$L$2:$L$334,{"A+","A","B+","B","B-","C"},Data!$B$2:$B$334,"HN-FX",Data!$I$2:$I$334,"MOB3+")) -> 7 | J40: =IF(I40=0,"",H40/I40) -> 0.14285714 | K40: =IF(OR(D40="",J40=""),"",(J40-D40)*100) -> 0
A41: HN1 | B41: =COUNTIFS(Data!$J$2:$J$334,"B-",Data!$B$2:$B$334,"HN1",Data!$G$2:$G$334,"MOB3+") -> 2 | C41: =SUMPRODUCT(COUNTIFS(Data!$J$2:$J$334,{"A+","A","B+","B","B-","C"},Data!$B$2:$B$334,"HN1",Data!$G$2:$G$334,"MOB3+")) -> 13 | D41: =IF(C41=0,"",B41/C41) -> 0.15384615 | E41: =COUNTIFS(Data!$K$2:$K$334,"B-",Data!$B$2:$B$334,"HN1",Data!$H$2:$H$334,"MOB3+") -> 1 | F41: =SUMPRODUCT(COUNTIFS(Data!$K$2:$K$334,{"A+","A","B+","B","B-","C"},Data!$B$2:$B$334,"HN1",Data!$H$2:$H$334,"MOB3+")) -> 13 | G41: =IF(F41=0,"",E41/F41) -> 0.076923077 | H41: =COUNTIFS(Data!$L$2:$L$334,"B-",Data!$B$2:$B$334,"HN1",Data!$I$2:$I$334,"MOB3+") -> 2 | I41: =SUMPRODUCT(COUNTIFS(Data!$L$2:$L$334,{"A+","A","B+","B","B-","C"},Data!$B$2:$B$334,"HN1",Data!$I$2:$I$334,"MOB3+")) -> 13 | J41: =IF(I41=0,"",H41/I41) -> 0.15384615 | K41: =IF(OR(D41="",J41=""),"",(J41-D41)*100) -> 0
A42: HN2 | B42: =COUNTIFS(Data!$J$2:$J$334,"B-",Data!$B$2:$B$334,"HN2",Data!$G$2:$G$334,"MOB3+") -> 2 | C42: =SUMPRODUCT(COUNTIFS(Data!$J$2:$J$334,{"A+","A","B+","B","B-","C"},Data!$B$2:$B$334,"HN2",Data!$G$2:$G$334,"MOB3+")) -> 10 | D42: =IF(C42=0,"",B42/C42) -> 0.2 | E42: =COUNTIFS(Data!$K$2:$K$334,"B-",Data!$B$2:$B$334,"HN2",Data!$H$2:$H$334,"MOB3+") -> 2 | F42: =SUMPRODUCT(COUNTIFS(Data!$K$2:$K$334,{"A+","A","B+","B","B-","C"},Data!$B$2:$B$334,"HN2",Data!$H$2:$H$334,"MOB3+")) -> 10 | G42: =IF(F42=0,"",E42/F42) -> 0.2 | H42: =COUNTIFS(Data!$L$2:$L$334,"B-",Data!$B$2:$B$334,"HN2",Data!$I$2:$I$334,"MOB3+") -> 0 | I42: =SUMPRODUCT(COUNTIFS(Data!$L$2:$L$334,{"A+","A","B+","B","B-","C"},Data!$B$2:$B$334,"HN2",Data!$I$2:$I$334,"MOB3+")) -> 10 | J42: =IF(I42=0,"",H42/I42) -> 0 | K42: =IF(OR(D42="",J42=""),"",(J42-D42)*100) -> -20
A43: HN3 | B43: =COUNTIFS(Data!$J$2:$J$334,"B-",Data!$B$2:$B$334,"HN3",Data!$G$2:$G$334,"MOB3+") -> 0 | C43: =SUMPRODUCT(COUNTIFS(Data!$J$2:$J$334,{"A+","A","B+","B","B-","C"},Data!$B$2:$B$334,"HN3",Data!$G$2:$G$334,"MOB3+")) -> 10 | D43: =IF(C43=0,"",B43/C43) -> 0 | E43: =COUNTIFS(Data!$K$2:$K$334,"B-",Data!$B$2:$B$334,"HN3",Data!$H$2:$H$334,"MOB3+") -> 2 | F43: =SUMPRODUCT(COUNTIFS(Data!$K$2:$K$334,{"A+","A","B+","B","B-","C"},Data!$B$2:$B$334,"HN3",Data!$H$2:$H$334,"MOB3+")) -> 11 | G43: =IF(F43=0,"",E43/F43) -> 0.18181818 | H43: =COUNTIFS(Data!$L$2:$L$334,"B-",Data!$B$2:$B$334,"HN3",Data!$I$2:$I$334,"MOB3+") -> 1 | I43: =SUMPRODUCT(COUNTIFS(Data!$L$2:$L$334,{"A+","A","B+","B","B-","C"},Data!$B$2:$B$334,"HN3",Data!$I$2:$I$334,"MOB3+")) -> 12 | J43: =IF(I43=0,"",H43/I43) -> 0.083333333 | K43: =IF(OR(D43="",J43=""),"",(J43-D43)*100) -> 8.3333333
A44: HN4 | B44: =COUNTIFS(Data!$J$2:$J$334,"B-",Data!$B$2:$B$334,"HN4",Data!$G$2:$G$334,"MOB3+") -> 0 | C44: =SUMPRODUCT(COUNTIFS(Data!$J$2:$J$334,{"A+","A","B+","B","B-","C"},Data!$B$2:$B$334,"HN4",Data!$G$2:$G$334,"MOB3+")) -> 7 | D44: =IF(C44=0,"",B44/C44) -> 0 | E44: =COUNTIFS(Data!$K$2:$K$334,"B-",Data!$B$2:$B$334,"HN4",Data!$H$2:$H$334,"MOB3+") -> 0 | F44: =SUMPRODUCT(COUNTIFS(Data!$K$2:$K$334,{"A+","A","B+","B","B-","C"},Data!$B$2:$B$334,"HN4",Data!$H$2:$H$334,"MOB3+")) -> 8 | G44: =IF(F44=0,"",E44/F44) -> 0 | H44: =COUNTIFS(Data!$L$2:$L$334,"B-",Data!$B$2:$B$334,"HN4",Data!$I$2:$I$334,"MOB3+") -> 1 | I44: =SUMPRODUCT(COUNTIFS(Data!$L$2:$L$334,{"A+","A","B+","B","B-","C"},Data!$B$2:$B$334,"HN4",Data!$I$2:$I$334,"MOB3+")) -> 9 | J44: =IF(I44=0,"",H44/I44) -> 0.11111111 | K44: =IF(OR(D44="",J44=""),"",(J44-D44)*100) -> 11.111111
A45: HN5 | B45: =COUNTIFS(Data!$J$2:$J$334,"B-",Data!$B$2:$B$334,"HN5",Data!$G$2:$G$334,"MOB3+") -> 1 | C45: =SUMPRODUCT(COUNTIFS(Data!$J$2:$J$334,{"A+","A","B+","B","B-","C"},Data!$B$2:$B$334,"HN5",Data!$G$2:$G$334,"MOB3+")) -> 11 | D45: =IF(C45=0,"",B45/C45) -> 0.090909091 | E45: =COUNTIFS(Data!$K$2:$K$334,"B-",Data!$B$2:$B$334,"HN5",Data!$H$2:$H$334,"MOB3+") -> 1 | F45: =SUMPRODUCT(COUNTIFS(Data!$K$2:$K$334,{"A+","A","B+","B","B-","C"},Data!$B$2:$B$334,"HN5",Data!$H$2:$H$334,"MOB3+")) -> 11 | G45: =IF(F45=0,"",E45/F45) -> 0.090909091 | H45: =COUNTIFS(Data!$L$2:$L$334,"B-",Data!$B$2:$B$334,"HN5",Data!$I$2:$I$334,"MOB3+") -> 2 | I45: =SUMPRODUCT(COUNTIFS(Data!$L$2:$L$334,{"A+","A","B+","B","B-","C"},Data!$B$2:$B$334,"HN5",Data!$I$2:$I$334,"MOB3+")) -> 12 | J45: =IF(I45=0,"",H45/I45) -> 0.16666667 | K45: =IF(OR(D45="",J45=""),"",(J45-D45)*100) -> 7.5757576
...

Sheet Transitions
A1: Ma trận dịch chuyển grade (số BD) — hàng = tháng trước, cột = tháng sau
A3: T8 → T9
A4: Từ \ Đến | B4: A+ | C4: A | D4: B+ | E4: B | F4: B- | G4: C | H4: - | I4: (trống) | J4: Tổng
A5: A+ | B5: =COUNTIFS(Data!$J$2:$J$334,"A+",Data!$K$2:$K$334,"A+") -> 4 | C5: =COUNTIFS(Data!$J$2:$J$334,"A+",Data!$K$2:$K$334,"A") -> 6 | D5: =COUNTIFS(Data!$J$2:$J$334,"A+",Data!$K$2:$K$334,"B+") -> 0 | E5: =COUNTIFS(Data!$J$2:$J$334,"A+",Data!$K$2:$K$334,"B") -> 2 | F5: =COUNTIFS(Data!$J$2:$J$334,"A+",Data!$K$2:$K$334,"B-") -> 0 | G5: =COUNTIFS(Data!$J$2:$J$334,"A+",Data!$K$2:$K$334,"C") -> 0 | H5: =COUNTIFS(Data!$J$2:$J$334,"A+",Data!$K$2:$K$334,"-") -> 0 | I5: =COUNTIFS(Data!$J$2:$J$334,"A+",Data!$K$2:$K$334,"") -> 0 | J5: =SUM(B5:I5) -> 12
A6: A | B6: =COUNTIFS(Data!$J$2:$J$334,"A",Data!$K$2:$K$334,"A+") -> 4 | C6: =COUNTIFS(Data!$J$2:$J$334,"A",Data!$K$2:$K$334,"A") -> 12 | D6: =COUNTIFS(Data!$J$2:$J$334,"A",Data!$K$2:$K$334,"B+") -> 9 | E6: =COUNTIFS(Data!$J$2:$J$334,"A",Data!$K$2:$K$334,"B") -> 8 | F6: =COUNTIFS(Data!$J$2:$J$334,"A",Data!$K$2:$K$334,"B-") -> 0 | G6: =COUNTIFS(Data!$J$2:$J$334,"A",Data!$K$2:$K$334,"C") -> 1 | H6: =COUNTIFS(Data!$J$2:$J$334,"A",Data!$K$2:$K$334,"-") -> 0 | I6: =COUNTIFS(Data!$J$2:$J$334,"A",Data!$K$2:$K$334,"") -> 1 | J6: =SUM(B6:I6) -> 35
A7: B+ | B7: =COUNTIFS(Data!$J$2:$J$334,"B+",Data!$K$2:$K$334,"A+") -> 4 | C7: =COUNTIFS(Data!$J$2:$J$334,"B+",Data!$K$2:$K$334,"A") -> 12 | D7: =COUNTIFS(Data!$J$2:$J$334,"B+",Data!$K$2:$K$334,"B+") -> 11 | E7: =COUNTIFS(Data!$J$2:$J$334,"B+",Data!$K$2:$K$334,"B") -> 11 | F7: =COUNTIFS(Data!$J$2:$J$334,"B+",Data!$K$2:$K$334,"B-") -> 5 | G7: =COUNTIFS(Data!$J$2:$J$334,"B+",Data!$K$2:$K$334,"C") -> 5 | H7: =COUNTIFS(Data!$J$2:$J$334,"B+",Data!$K$2:$K$334,"-") -> 0 | I7: =COUNTIFS(Data!$J$2:$J$334,"B+",Data!$K$2:$K$334,"") -> 0 | J7: =SUM(B7:I7) -> 48
A8: B | B8: =COUNTIFS(Data!$J$2:$J$334,"B",Data!$K$2:$K$334,"A+") -> 1 | C8: =COUNTIFS(Data!$J$2:$J$334,"B",Data!$K$2:$K$334,"A") -> 4 | D8: =COUNTIFS(Data!$J$2:$J$334,"B",Data!$K$2:$K$334,"B+") -> 9 | E8: =COUNTIFS(Data!$J$2:$J$334,"B",Data!$K$2:$K$334,"B") -> 16 | F8: =COUNTIFS(Data!$J$2:$J$334,"B",Data!$K$2:$K$334,"B-") -> 3 | G8: =COUNTIFS(Data!$J$2:$J$334,"B",Data!$K$2:$K$334,"C") -> 4 | H8: =COUNTIFS(Data!$J$2:$J$334,"B",Data!$K$2:$K$334,"-") -> 0 | I8: =COUNTIFS(Data!$J$2:$J$334,"B",Data!$K$2:$K$334,"") -> 0 | J8: =SUM(B8:I8) -> 37
A9: B- | B9: =COUNTIFS(Data!$J$2:$J$334,"B-",Data!$K$2:$K$334,"A+") -> 0 | C9: =COUNTIFS(Data!$J$2:$J$334,"B-",Data!$K$2:$K$334,"A") -> 3 | D9: =COUNTIFS(Data!$J$2:$J$334,"B-",Data!$K$2:$K$334,"B+") -> 2 | E9: =COUNTIFS(Data!$J$2:$J$334,"B-",Data!$K$2:$K$334,"B") -> 7 | F9: =COUNTIFS(Data!$J$2:$J$334,"B-",Data!$K$2:$K$334,"B-") -> 7 | G9: =COUNTIFS(Data!$J$2:$J$334,"B-",Data!$K$2:$K$334,"C") -> 3 | H9: =COUNTIFS(Data!$J$2:$J$334,"B-",Data!$K$2:$K$334,"-") -> 0 | I9: =COUNTIFS(Data!$J$2:$J$334,"B-",Data!$K$2:$K$334,"") -> 0 | J9: =SUM(B9:I9) -> 22
A10: C | B10: =COUNTIFS(Data!$J$2:$J$334,"C",Data!$K$2:$K$334,"A+") -> 0 | C10: =COUNTIFS(Data!$J$2:$J$334,"C",Data!$K$2:$K$334,"A") -> 0 | D10: =COUNTIFS(Data!$J$2:$J$334,"C",Data!$K$2:$K$334,"B+") -> 1 | E10: =COUNTIFS(Data!$J$2:$J$334,"C",Data!$K$2:$K$334,"B") -> 10 | F10: =COUNTIFS(Data!$J$2:$J$334,"C",Data!$K$2:$K$334,"B-") -> 6 | G10: =COUNTIFS(Data!$J$2:$J$334,"C",Data!$K$2:$K$334,"C") -> 41 | H10: =COUNTIFS(Data!$J$2:$J$334,"C",Data!$K$2:$K$334,"-") -> 0 | I10: =COUNTIFS(Data!$J$2:$J$334,"C",Data!$K$2:$K$334,"") -> 19 | J10: =SUM(B10:I10) -> 77
A11: - | B11: =COUNTIFS(Data!$J$2:$J$334,"-",Data!$K$2:$K$334,"A+") -> 0 | C11: =COUNTIFS(Data!$J$2:$J$334,"-",Data!$K$2:$K$334,"A") -> 0 | D11: =COUNTIFS(Data!$J$2:$J$334,"-",Data!$K$2:$K$334,"B+") -> 1 | E11: =COUNTIFS(Data!$J$2:$J$334,"-",Data!$K$2:$K$334,"B") -> 0 | F11: =COUNTIFS(Data!$J$2:$J$334,"-",Data!$K$2:$K$334,"B-") -> 2 | G11: =COUNTIFS(Data!$J$2:$J$334,"-",Data!$K$2:$K$334,"C") -> 17 | H11: =COUNTIFS(Data!$J$2:$J$334,"-",Data!$K$2:$K$334,"-") -> 0 | I11: =COUNTIFS(Data!$J$2:$J$334,"-",Data!$K$2:$K$334,"") -> 1 | J11: =SUM(B11:I11) -> 21
A12: (trống) | B12: =COUNTIFS(Data!$J$2:$J$334,"",Data!$K$2:$K$334,"A+") -> 0 | C12: =COUNTIFS(Data!$J$2:$J$334,"",Data!$K$2:$K$334,"A") -> 0 | D12: =COUNTIFS(Data!$J$2:$J$334,"",Data!$K$2:$K$334,"B+") -> 1 | E12: =COUNTIFS(Data!$J$2:$J$334,"",Data!$K$2:$K$334,"B") -> 0 | F12: =COUNTIFS(Data!$J$2:$J$334,"",Data!$K$2:$K$334,"B-") -> 0 | G12: =COUNTIFS(Data!$J$2:$J$334,"",Data!$K$2:$K$334,"C") -> 15 | H12: =COUNTIFS(Data!$J$2:$J$334,"",Data!$K$2:$K$334,"-") -> 17 | I12: =COUNTIFS(Data!$J$2:$J$334,"",Data!$K$2:$K$334,"") -> 46 | J12: =SUM(B12:I12) -> 79
A14: Số phận BD B- (T8)
A15: Lên ≥B | B15: =SUM(B9:E9) -> 12 | C15: =IF($B$19=0,"",B15/$B$19) -> 0.54545455
A16: Giữ B- | B16: =F9 -> 7 | C16: =IF($B$19=0,"",B16/$B$19) -> 0.31818182
A17: Rớt C | B17: =G9 -> 3 | C17: =IF($B$19=0,"",B17/$B$19) -> 0.13636364
A18: Không còn grade / nghỉ | B18: =H9+I9 -> 0 | C18: =IF($B$19=0,"",B18/$B$19) -> 0
A19: Tổng B- | B19: =J9 -> 22 | C19: =IF($B$19=0,"",B19/$B$19) -> 1
A21: Nguồn BD B- (T9)
A22: Rớt từ ≥B | B22: =SUM(F5:F8) -> 8 | C22: =IF($B$26=0,"",B22/$B$26) -> 0.34782609
A23: Giữ B- | B23: =F9 -> 7 | C23: =IF($B$26=0,"",B23/$B$26) -> 0.30434783
A24: Lên từ C | B24: =F10 -> 6 | C24: =IF($B$26=0,"",B24/$B$26) -> 0.26086957
A25: BD mới / chưa grade | B25: =F11+F12 -> 2 | C25: =IF($B$26=0,"",B25/$B$26) -> 0.086956522
A26: Tổng B- | B26: =SUM(F5:F12) -> 23 | C26: =IF($B$26=0,"",B26/$B$26) -> 1
A29: T9 → T10 MTD
A30: Từ \ Đến | B30: A+ | C30: A | D30: B+ | E30: B | F30: B- | G30: C | H30: - | I30: (trống) | J30: Tổng
A31: A+ | B31: =COUNTIFS(Data!$K$2:$K$334,"A+",Data!$L$2:$L$334,"A+") -> 7 | C31: =COUNTIFS(Data!$K$2:$K$334,"A+",Data!$L$2:$L$334,"A") -> 2 | D31: =COUNTIFS(Data!$K$2:$K$334,"A+",Data!$L$2:$L$334,"B+") -> 0 | E31: =COUNTIFS(Data!$K$2:$K$334,"A+",Data!$L$2:$L$334,"B") -> 1 | F31: =COUNTIFS(Data!$K$2:$K$334,"A+",Data!$L$2:$L$334,"B-") -> 1 | G31: =COUNTIFS(Data!$K$2:$K$334,"A+",Data!$L$2:$L$334,"C") -> 2 | H31: =COUNTIFS(Data!$K$2:$K$334,"A+",Data!$L$2:$L$334,"-") -> 0 | I31: =COUNTIFS(Data!$K$2:$K$334,"A+",Data!$L$2:$L$334,"") -> 0 | J31: =SUM(B31:I31) -> 13
A32: A | B32: =COUNTIFS(Data!$K$2:$K$334,"A",Data!$L$2:$L$334,"A+") -> 3 | C32: =COUNTIFS(Data!$K$2:$K$334,"A",Data!$L$2:$L$334,"A") -> 17 | D32: =COUNTIFS(Data!$K$2:$K$334,"A",Data!$L$2:$L$334,"B+") -> 10 | E32: =COUNTIFS(Data!$K$2:$K$334,"A",Data!$L$2:$L$334,"B") -> 3 | F32: =COUNTIFS(Data!$K$2:$K$334,"A",Data!$L$2:$L$334,"B-") -> 3 | G32: =COUNTIFS(Data!$K$2:$K$334,"A",Data!$L$2:$L$334,"C") -> 1 | H32: =COUNTIFS(Data!$K$2:$K$334,"A",Data!$L$2:$L$334,"-") -> 0 | I32: =COUNTIFS(Data!$K$2:$K$334,"A",Data!$L$2:$L$334,"") -> 0 | J32: =SUM(B32:I32) -> 37
A33: B+ | B33: =COUNTIFS(Data!$K$2:$K$334,"B+",Data!$L$2:$L$334,"A+") -> 1 | C33: =COUNTIFS(Data!$K$2:$K$334,"B+",Data!$L$2:$L$334,"A") -> 8 | D33: =COUNTIFS(Data!$K$2:$K$334,"B+",Data!$L$2:$L$334,"B+") -> 12 | E33: =COUNTIFS(Data!$K$2:$K$334,"B+",Data!$L$2:$L$334,"B") -> 7 | F33: =COUNTIFS(Data!$K$2:$K$334,"B+",Data!$L$2:$L$334,"B-") -> 5 | G33: =COUNTIFS(Data!$K$2:$K$334,"B+",Data!$L$2:$L$334,"C") -> 1 | H33: =COUNTIFS(Data!$K$2:$K$334,"B+",Data!$L$2:$L$334,"-") -> 0 | I33: =COUNTIFS(Data!$K$2:$K$334,"B+",Data!$L$2:$L$334,"") -> 0 | J33: =SUM(B33:I33) -> 34
A34: B | B34: =COUNTIFS(Data!$K$2:$K$334,"B",Data!$L$2:$L$334,"A+") -> 2 | C34: =COUNTIFS(Data!$K$2:$K$334,"B",Data!$L$2:$L$334,"A") -> 7 | D34: =COUNTIFS(Data!$K$2:$K$334,"B",Data!$L$2:$L$334,"B+") -> 18 | E34: =COUNTIFS(Data!$K$2:$K$334,"B",Data!$L$2:$L$334,"B") -> 15 | F34: =COUNTIFS(Data!$K$2:$K$334,"B",Data!$L$2:$L$334,"B-") -> 6 | G34: =COUNTIFS(Data!$K$2:$K$334,"B",Data!$L$2:$L$334,"C") -> 5 | H34: =COUNTIFS(Data!$K$2:$K$334,"B",Data!$L$2:$L$334,"-") -> 0 | I34: =COUNTIFS(Data!$K$2:$K$334,"B",Data!$L$2:$L$334,"") -> 1 | J34: =SUM(B34:I34) -> 54
A35: B- | B35: =COUNTIFS(Data!$K$2:$K$334,"B-",Data!$L$2:$L$334,"A+") -> 0 | C35: =COUNTIFS(Data!$K$2:$K$334,"B-",Data!$L$2:$L$334,"A") -> 1 | D35: =COUNTIFS(Data!$K$2:$K$334,"B-",Data!$L$2:$L$334,"B+") -> 6 | E35: =COUNTIFS(Data!$K$2:$K$334,"B-",Data!$L$2:$L$334,"B") -> 4 | F35: =COUNTIFS(Data!$K$2:$K$334,"B-",Data!$L$2:$L$334,"B-") -> 5 | G35: =COUNTIFS(Data!$K$2:$K$334,"B-",Data!$L$2:$L$334,"C") -> 7 | H35: =COUNTIFS(Data!$K$2:$K$334,"B-",Data!$L$2:$L$334,"-") -> 0 | I35: =COUNTIFS(Data!$K$2:$K$334,"B-",Data!$L$2:$L$334,"") -> 0 | J35: =SUM(B35:I35) -> 23
A36: C | B36: =COUNTIFS(Data!$K$2:$K$334,"C",Data!$L$2:$L$334,"A+") -> 0 | C36: =COUNTIFS(Data!$K$2:$K$334,"C",Data!$L$2:$L$334,"A") -> 1 | D36: =COUNTIFS(Data!$K$2:$K$334,"C",Data!$L$2:$L$334,"B+") -> 3 | E36: =COUNTIFS(Data!$K$2:$K$334,"C",Data!$L$2:$L$334,"B") -> 10 | F36: =COUNTIFS(Data!$K$2:$K$334,"C",Data!$L$2:$L$334,"B-") -> 4 | G36: =COUNTIFS(Data!$K$2:$K$334,"C",Data!$L$2:$L$334,"C") -> 32 | H36: =COUNTIFS(Data!$K$2:$K$334,"C",Data!$L$2:$L$334,"-") -> 0 | I36: =COUNTIFS(Data!$K$2:$K$334,"C",Data!$L$2:$L$334,"") -> 38 | J36: =SUM(B36:I36) -> 88
A37: - | B37: =COUNTIFS(Data!$K$2:$K$334,"-",Data!$L$2:$L$334,"A+") -> 0 | C37: =COUNTIFS(Data!$K$2:$K$334,"-",Data!$L$2:$L$334,"A") -> 0 | D37: =COUNTIFS(Data!$K$2:$K$334,"-",Data!$L$2:$L$334,"B+") -> 0 | E37: =COUNTIFS(Data!$K$2:$K$334,"-",Data!$L$2:$L$334,"B") -> 0 | F37: =COUNTIFS(Data!$K$2:$K$334,"-",Data!$L$2:$L$334,"B-") -> 1 | G37: =COUNTIFS(Data!$K$2:$K$334,"-",Data!$L$2:$L$334,"C") -> 14 | H37: =COUNTIFS(Data!$K$2:$K$334,"-",Data!$L$2:$L$334,"-") -> 0 | I37: =COUNTIFS(Data!$K$2:$K$334,"-",Data!$L$2:$L$334,"") -> 2 | J37: =SUM(B37:I37) -> 17
A38: (trống) | B38: =COUNTIFS(Data!$K$2:$K$334,"",Data!$L$2:$L$334,"A+") -> 0 | C38: =COUNTIFS(Data!$K$2:$K$334,"",Data!$L$2:$L$334,"A") -> 0 | D38: =COUNTIFS(Data!$K$2:$K$334,"",Data!$L$2:$L$334,"B+") -> 0 | E38: =COUNTIFS(Data!$K$2:$K$334,"",Data!$L$2:$L$334,"B") -> 0 | F38: =COUNTIFS(Data!$K$2:$K$334,"",Data!$L$2:$L$334,"B-") -> 0 | G38: =COUNTIFS(Data!$K$2:$K$334,"",Data!$L$2:$L$334,"C") -> 18 | H38: =COUNTIFS(Data!$K$2:$K$334,"",Data!$L$2:$L$334,"-") -> 0 | I38: =COUNTIFS(Data!$K$2:$K$334,"",Data!$L$2:$L$334,"") -> 49 | J38: =SUM(B38:I38) -> 67
A40: Số phận BD B- (T9)
A41: Lên ≥B | B41: =SUM(B35:E35) -> 11 | C41: =IF($B$45=0,"",B41/$B$45) -> 0.47826087
A42: Giữ B- | B42: =F35 -> 5 | C42: =IF($B$45=0,"",B42/$B$45) -> 0.2173913
A43: Rớt C | B43: =G35 -> 7 | C43: =IF($B$45=0,"",B43/$B$45) -> 0.30434783
A44: Không còn grade / nghỉ | B44: =H35+I35 -> 0 | C44: =IF($B$45=0,"",B44/$B$45) -> 0
A45: Tổng B- | B45: =J35 -> 23 | C45: =IF($B$45=0,"",B45/$B$45) -> 1
A47: Nguồn BD B- (T10 MTD)
...

Sheet Data
A1: No | B1: Team | C1: Region | D1: Segment | E1: Status T10 MTD | F1: Status T9 | G1: MOB T8 | H1: MOB T9 | I1: MOB T10 | J1: Grade T8 | K1: Grade T9 | L1: Grade T10 MTD
A2: 1 | B2: HN-F2 | C2: North | D2: FS | E2: Active | F2: Active | G2: MOB3+ | H2: MOB3+ | I2: MOB3+ | J2: B | K2: B+ | L2: B-
A3: 2 | B3: HCM2 | C3: South | D3: SME | E3: Active | F3: Active | G3: MOB3+ | H3: MOB3+ | I3: MOB3+ | J3: A | K3: B+ | L3: B-
A4: 3 | B4: HN-F3 | C4: North | D4: FS | E4: Active | F4: Active | G4: MOB3+ | H4: MOB3+ | I4: MOB3+ | J4: B | K4: B+ | L4: A
A5: 4 | B5: HN-F5 | C5: North | D5: FS | E5: Active | F5: Active | G5: MOB1 | H5: MOB2 | I5: MOB3+ | J5: C | K5: B+ | L5: B
A6: 5 | B6: HN6 | C6: North | D6: SME | E6: Active | F6: Active | G6: MOB3+ | H6: MOB3+ | I6: MOB3+ | J6: A | K6: B+ | L6: B+
A7: 6 | B7: HN-F5 | C7: North | D7: FS | E7: Active | F7: Active | G7: MOB3+ | H7: MOB3+ | I7: MOB3+ | J7: B+ | K7: B+ | L7: B
A8: 7 | B8: HCM4 | C8: South | D8: SME | E8: Active | F8: Active | G8: MOB3+ | H8: MOB3+ | I8: MOB3+ | J8: B | K8: B | L8: B+
A9: 8 | B9: HN5 | C9: North | D9: SME | E9: Active | F9: Active | G9: MOB1 | H9: MOB2 | I9: MOB3+ | J9: C | K9: C | L9: B-
A10: 9 | B10: HCM2 | C10: South | D10: SME | E10: Active | F10: Active | G10: MOB3+ | H10: MOB3+ | I10: MOB3+ | J10: B+ | K10: B | L10: B
A11: 10 | B11: HCM3 | C11: South | D11: SME | E11: Active | F11: Active | H11: MOB0 | I11: MOB1 | K11: - | L11: B-
A12: 11 | B12: HN-F4 | C12: North | D12: FS | E12: Active | F12: Active | G12: MOB3+ | H12: MOB3+ | I12: MOB3+ | J12: C | K12: C | L12: C
A13: 12 | B13: HN1 | C13: North | D13: SME | E13: Active | F13: Active | G13: MOB3+ | H13: MOB3+ | I13: MOB3+ | J13: A | K13: A+ | L13: A+
A14: 13 | B14: HN6 | C14: North | D14: SME | E14: Active | F14: Active | G14: MOB3+ | H14: MOB3+ | I14: MOB3+ | J14: B | K14: B | L14: B-
A15: 14 | B15: North-F1 | C15: North | D15: FS | E15: Active | F15: Active | G15: MOB3+ | H15: MOB3+ | I15: MOB3+ | J15: B | K15: B | L15: B
A16: 15 | B16: HCM5 | C16: South | D16: SME | E16: Active | F16: Active | G16: MOB0 | H16: MOB1 | I16: MOB2 | J16: - | K16: C | L16: B-
A17: 16 | B17: HN1 | C17: North | D17: SME | E17: Active | F17: Active | G17: MOB3+ | H17: MOB3+ | I17: MOB3+ | J17: B- | K17: A | L17: B+
A18: 17 | B18: BCI HCM | C18: South | D18: BCI | G18: MOB3+ | J18: C
A19: 18 | B19: HN-F5 | C19: North | D19: FS | F19: Inactive | G19: MOB1 | H19: MOB2 | J19: C | K19: C
A20: 19 | B20: HCM1 | C20: South | D20: SME | G20: MOB3+ | J20: C
A21: 20 | B21: HN-F5 | C21: North | D21: FS | F21: Inactive | G21: MOB2 | H21: MOB3+ | J21: C | K21: C
A22: 21 | B22: HCM2 | C22: South | D22: SME
A23: 22 | B23: HCM1 | C23: South | D23: SME | E23: Active | F23: Active | G23: MOB3+ | H23: MOB3+ | I23: MOB3+ | J23: B+ | K23: C | L23: A
A24: 23 | B24: HCM2 | C24: South | D24: SME | E24: Active | F24: Active | G24: MOB3+ | H24: MOB3+ | I24: MOB3+ | J24: B+ | K24: A | L24: B-
A25: 24 | B25: HCM4 | C25: South | D25: SME | E25: Active | F25: Active | G25: MOB2 | H25: MOB3+ | I25: MOB3+ | J25: B | K25: B | L25: B
A26: 25 | B26: HN3 | C26: North | D26: SME | E26: Active | F26: Active | G26: MOB3+ | H26: MOB3+ | I26: MOB3+ | J26: B+ | K26: A | L26: B
A27: 26 | B27: HN-F2 | C27: North | D27: FS | E27: Active | F27: Active | G27: MOB3+ | H27: MOB3+ | I27: MOB3+ | J27: B- | K27: C | L27: B
A28: 27 | B28: HN5 | C28: North | D28: SME | E28: Active | F28: Active | G28: MOB3+ | H28: MOB3+ | I28: MOB3+ | J28: A | K28: A | L28: B+
A29: 28 | B29: HN-F6 | C29: North | D29: FS | E29: Active | F29: Active | G29: MOB3+ | H29: MOB3+ | I29: MOB3+ | J29: B | K29: C | L29: B
A30: 29 | B30: HCM5 | C30: South | D30: SME | E30: Active | F30: Active | G30: MOB1 | H30: MOB2 | I30: MOB3+ | J30: B+ | K30: A | L30: A
A31: 30 | B31: HCM1 | C31: South | D31: SME | E31: Active | F31: Active | G31: MOB3+ | H31: MOB3+ | I31: MOB3+ | J31: A | K31: B | L31: A
A32: 31 | B32: HCM3 | C32: South | D32: SME | E32: Active | F32: Active | G32: MOB3+ | H32: MOB3+ | I32: MOB3+ | J32: A+ | K32: A | L32: A+
A33: 32 | B33: HN2 | C33: North | D33: SME | E33: Active | F33: Active | G33: MOB3+ | H33: MOB3+ | I33: MOB3+ | J33: A | K33: A | L33: A
A34: 33 | B34: HN4 | C34: North | D34: SME | E34: Active | F34: Active | G34: MOB3+ | H34: MOB3+ | I34: MOB3+ | J34: B+ | K34: B | L34: A
A35: 34 | B35: HN-F4 | C35: North | D35: FS | E35: Active | F35: Active | G35: MOB3+ | H35: MOB3+ | I35: MOB3+ | J35: C | K35: C | L35: B
A36: 35 | B36: HN-F5 | C36: North | D36: FS | F36: Inactive | G36: MOB3+ | H36: MOB3+ | J36: C | K36: C
A37: 36 | B37: HN1 | C37: North | D37: SME | E37: Active | F37: Active | G37: MOB3+ | H37: MOB3+ | I37: MOB3+ | J37: B+ | K37: B+ | L37: B-
A38: 37 | B38: North-F1 | C38: North | D38: FS | E38: Active | F38: Active | G38: MOB3+ | H38: MOB3+ | I38: MOB3+ | J38: B | K38: A | L38: A
A39: 38 | B39: HN-F6 | C39: North | D39: FS | E39: Active | F39: Active | G39: MOB3+ | H39: MOB3+ | I39: MOB3+ | J39: C | K39: C | L39: C
A40: 39 | B40: HN-F4 | C40: North | D40: FS | F40: Inactive | G40: MOB3+ | H40: MOB3+ | J40: C | K40: C
...

Sheet Ghi chú
A1: Ghi chú phương pháp
A3: Nguồn | B3: Google Sheet "[Internal SC] Grade C monitoring" → sheet "[SC] Data raw C movement" (lấy 16/10/2026). M-2 = T8, M-1 = T9, MTD = T10 chốt 15/10/2026.
A4: Phạm vi | B4: 333 BD có trong sheet nguồn (gồm cả BD đã nghỉ trong kỳ). Đã bỏ email BD.
A5: Định nghĩa %B- | B5: #BD grade B- ÷ #BD có grade A+/A/B+/B/B-/C trong tháng đó. Loại grade "-" (MOB0) và ô trống.
A6: Giả định – Region | B6: Suy từ tên team: HN*/North* → North; HCM*/BCI HCM → South.
A7: Giả định – Team/Segment | B7: Theo team MTD (hoặc team cuối cùng nếu đã nghỉ). BD chuyển team trong kỳ được tính vào team hiện tại.
A8: Giới hạn | B8: T10 là MTD 15/10, chưa chốt. Team 10–14 BD → 1 BD ≈ 7–10 điểm %, đọc như tín hiệu, không phải kết luận.
A9: Cách cập nhật | B9: Dán đè data mới vào sheet Data (giữ đúng cột). Các sheet Summary và Transitions tự tính lại bằng COUNTIFS. Nếu số dòng tăng, mở rộng range trong công thức (hiện tới dòng 334).
